Workbook

Sheet case study overview
G1: CASE STUDY
R2: ROLE | S2: Financial Planning Analyst
G3: FINANCIAL PLANNING FOR PRIYA
A6: BUSINESS CONTEXT | C6: Priya is a 25-year-old marketing executive based in Delhi who recently started her professional career. Although she earns a stable monthly income, she finds it difficult to balance day-to-day expenses, savings, and multiple financial goals. Like many young professionals, she wants to improve her financial discipline while preparing for both expected and unexpected life events. This case study develops a structured financial planning model to help Priya manage her cash flow, prioritize her goals, and move toward long-term financial independence. | M6: CLIENT PROFILE | R6: KEY PERFORMANCE INDICATORS (KPIs)
M7: Item | O7: Details | R7: Financial Health | T7: Goal Tracking
M8: Name | O8: Priya Sharma (Fictional) | R8: Monthly Income | T8: Goal Progress (%)
M9: Age | O9: 25 Years | R9: Total Expenses | T9: Emergency Fund Completion
M10: City | O10: Delhi | R10: Monthly Savings | T10: Goal Completion Timeline
A11: BUSINESS PROBLEM | C11: How should Priya allocate her monthly income to achieve multiple financial goals while maintaining sufficient liquidity, managing financial risks, and improving her overall financial well-being? | M11: Occupation | O11: Marketing Executive | R11: Savings Rate (%) | T11: Scenario Comparison
M12: Monthly Salary | O12: 52000 | R12: Net Cash Flow | T12: Five-Year Savings Projection
M13: Planning Horizon | O13: 5 Years
A14: PROJECT OBJECTIVES | C14: •Develop a realistic monthly budget. •Analyze Priya's income and spending patterns. •Build and monitor an emergency fund. •Track progress toward short-term and long-term financial goals. •Evaluate different savings scenarios. •Provide practical financial recommendations based on the analysis. | M14: Currency | O14: INR
M16: MODEL ASSUMPTIONS | R16: FINANCIAL GOALS
M17: Assumption | O17: Value | R17: Goal | S17: Target Amount | T17: Timeline | U17: Priority
M18: Monthly Salary | O18: 52000 | R18: Emergency Fund | S18: 150000 | T18: 12 Months | U18: High
A19: PROJECT SCOPE | C19: Included ✓ | D19: Monthly Budgeting | E19: Cash Flow Analysis | F19: Savings Planning | G19: Emergency Fund Planning | H19: Goal Tracking | I19: Scenario Analysis | M19: Annual Salary Growth | O19: 0.08 | R19: Parents Support | S19: ₹5,000/month | T19: Ongoing | U19: High
M20: Inflation Rate | O20: 0.06 | R20: MBA Fund | S20: 500000 | T20: 3 Years | U20: High
C21: Excluded ✕ | D21: Retirement Planning | E21: Investment Portfolio Selection | F21: Mutual Fund Recommendations | G21: Tax Planning | H21: Insurance Planning | I21: Loan Optimization | M21: Annual Bonus | O21: 30000 | R21: Vacation | S21: 30000 | T21: 6 Months | U21: Medium
M22: Promotion | O22: Beginning of Year 2 | R22: House Down Payment | S22: 1000000 | T22: 7 Years | U22: Medium
A23: Project Methodology | C23: Business Understanding → Data Collection → Financial analysis → Dashboard Development → Insigts & Recommendations | M23: Budget Frequency | O23: Monthly
M24: Planning Period | O24: 5 Years

Sheet Data
A1: DATA
A3: MONTHLY INCOME
A4: Month | B4: Salary | C4: Bonus | D4: Other Income | E4: Total Income
A5: January | B5: 52000 | C5: 0 | D5: 0 | E5: =SUM(B5:D5) -> 52000
A6: February | B6: 52000 | C6: 0 | D6: 2000 | E6: =SUM(B6:D6) -> 54000
A7: March | B7: 52000 | C7: 0 | D7: 0 | E7: =SUM(B7:D7) -> 52000
A8: April | B8: 52000 | C8: 0 | D8: 1500 | E8: =SUM(B8:D8) -> 53500
A9: May | B9: 52000 | C9: 0 | D9: 0 | E9: =SUM(B9:D9) -> 52000
A10: June | B10: 52000 | C10: 0 | D10: 2500 | E10: =SUM(B10:D10) -> 54500
A11: July | B11: 52000 | C11: 30000 | D11: 0 | E11: =SUM(B11:D11) -> 82000
A12: August | B12: 52000 | C12: 0 | D12: 0 | E12: =SUM(B12:D12) -> 52000
A13: September | B13: 52000 | C13: 0 | D13: 0 | E13: =SUM(B13:D13) -> 52000
A14: October | B14: 52000 | C14: 0 | D14: 1000 | E14: =SUM(B14:D14) -> 53000
A15: November | B15: 52000 | C15: 0 | D15: 0 | E15: =SUM(B15:D15) -> 52000
A16: December | B16: 52000 | C16: 0 | D16: 3000 | E16: =SUM(B16:D16) -> 55000
A17: Total | B17: =SUBTOTAL(109,Table2[Salary]) -> 624000 | C17: =SUBTOTAL(109,Table2[Bonus]) -> 30000 | D17: =SUBTOTAL(109,Table2[Other Income]) -> 10000 | E17: =SUBTOTAL(109,Table2[Total Income]) -> 664000
A19: MONTHLY EXPENSE
A20: Month | B20: Rent | C20: Food | D20: Utilities | E20: Transport | F20: Shopping | G20: Entertainment | H20: Parents Support | I20: Misc. | J20: Total Expenses
A21: January | B21: 15000 | C21: 6000 | D21: 2500 | E21: 2500 | F21: 3000 | G21: 2000 | H21: 5000 | I21: 1500 | J21: =SUM(B21:I21) -> 37500
A22: February | B22: 15000 | C22: 6200 | D22: 2600 | E22: 2400 | F22: 2500 | G22: 2500 | H22: 5000 | I22: 1200 | J22: =SUM(B22:I22) -> 37400
A23: March | B23: 15000 | C23: 6300 | D23: 2700 | E23: 2600 | F23: 4000 | G23: 2500 | H23: 5000 | I23: 41500 | J23: =SUM(B23:I23) -> 79600
A24: April | B24: 15000 | C24: 6100 | D24: 2500 | E24: 2500 | F24: 2000 | G24: 1800 | H24: 5000 | I24: 1000 | J24: =SUM(B24:I24) -> 35900
A25: May | B25: 15000 | C25: 6400 | D25: 2700 | E25: 2600 | F25: 2500 | G25: 2000 | H25: 5000 | I25: 1500 | J25: =SUM(B25:I25) -> 37700
A26: June | B26: 15000 | C26: 6500 | D26: 2800 | E26: 2700 | F26: 3000 | G26: 2500 | H26: 5000 | I26: 1800 | J26: =SUM(B26:I26) -> 39300
A27: July | B27: 15000 | C27: 6300 | D27: 2700 | E27: 2600 | F27: 4500 | G27: 3500 | H27: 5000 | I27: 2000 | J27: =SUM(B27:I27) -> 41600
A28: August | B28: 15000 | C28: 6400 | D28: 2700 | E28: 2500 | F28: 2500 | G28: 2000 | H28: 5000 | I28: 1500 | J28: =SUM(B28:I28) -> 37600
A29: September | B29: 15000 | C29: 6500 | D29: 2800 | E29: 2700 | F29: 2500 | G29: 2000 | H29: 5000 | I29: 26500 | J29: =SUM(B29:I29) -> 63000
A30: October | B30: 15000 | C30: 6400 | D30: 2700 | E30: 2500 | F30: 3500 | G30: 2500 | H30: 5000 | I30: 1500 | J30: =SUM(B30:I30) -> 39100
A31: November | B31: 15000 | C31: 6300 | D31: 2700 | E31: 2600 | F31: 2000 | G31: 2000 | H31: 5000 | I31: 1300 | J31: =SUM(B31:I31) -> 36900
A32: December | B32: 15000 | C32: 6800 | D32: 3000 | E32: 2700 | F32: 5000 | G32: 4000 | H32: 5000 | I32: 2500 | J32: =SUM(B32:I32) -> 44000
A33: Total | B33: =SUBTOTAL(109,Table3[Rent]) -> 180000 | C33: =SUBTOTAL(109,Table3[Food]) -> 76200 | D33: =SUBTOTAL(109,Table3[Utilities]) -> 32400 | E33: =SUBTOTAL(109,Table3[Transport]) -> 30900 | F33: =SUBTOTAL(109,Table3[Shopping]) -> 37000 | G33: =SUBTOTAL(109,Table3[Entertainment]) -> 29300 | H33: =SUBTOTAL(109,Table3[Parents Support]) -> 60000 | I33: =SUBTOTAL(109,Table3[Misc.]) -> 83800 | J33: =SUBTOTAL(109,Table3[Total Expenses]) -> 529600
A35: FINANCIAL GOALS
A36: Goal | B36: Target Amount | C36: Timeline (Months) | D36: Priority | E36: Monthly Saving Required | F36: Current Saved
A37: Emergency Fund | B37: 150000 | C37: 12 | D37: High | E37: =B37/C37 -> 12500 | F37: 0
A38: Parents Support | B38: 5000 | C38: Ongoing | D38: High | E38: N/A | F38: N/A
A39: MBA Fund | B39: 500000 | C39: 36 | D39: High | E39: =B39/C39 -> 13888.889 | F39: 0
A40: Vacation | B40: 30000 | C40: 6 | D40: Medium | E40: =B40/C40 -> 5000 | F40: 0
A41: House Down Payment | B41: 1000000 | C41: 84 | D41: Medium | E41: =B41/C41 -> 11904.762 | F41: 0
A43: UNEXPECTED EVENTS
A44: Month | B44: Event | C44: Type | D44: Amount | E44: Impact
...

Sheet Analysis
A1: FINANCIAL ANALYSIS
A3: MONTHLY FINANCIAL PERFORMANCE | H3: ANNUAL FINANCIAL SUMMARY
A4: Month | B4: Total Income | C4: Total Expenses | D4: Monthly Savings | E4: Savings Rate % | H4: KPI | J4: Formula
A5: January | B5: =Table2[[#This Row],[Total Income]] -> 52000 | C5: =Data!J21 -> 37500 | D5: =B5-C5 -> 14500 | E5: =D5/B5 -> 0.27884615 | H5: Annual Income | J5: =Table2[[#Totals],[Total Income]] -> 664000
A6: February | B6: =Table2[[#This Row],[Total Income]] -> 54000 | C6: =Data!J22 -> 37400 | D6: =B6-C6 -> 16600 | E6: =D6/B6 -> 0.30740741 | H6: Annual Expenses | J6: =Table3[[#Totals],[Total Expenses]] -> 529600
A7: March | B7: =Table2[[#This Row],[Total Income]] -> 52000 | C7: =Data!J23 -> 79600 | D7: =B7-C7 -> -27600 | E7: =D7/B7 -> -0.53076923 | H7: Annual Savings | J7: =J5-J6 -> 134400
A8: April | B8: =Table2[[#This Row],[Total Income]] -> 53500 | C8: =Data!J24 -> 35900 | D8: =B8-C8 -> 17600 | E8: =D8/B8 -> 0.32897196 | H8: Annual Savings Rate | J8: =J7/J5 -> 0.20240964
A9: May | B9: =Table2[[#This Row],[Total Income]] -> 52000 | C9: =Data!J25 -> 37700 | D9: =B9-C9 -> 14300 | E9: =D9/B9 -> 0.275 | H9: Average Monthly Income | J9: =AVERAGE(B5:B16) -> 55333.333
A10: June | B10: =Table2[[#This Row],[Total Income]] -> 54500 | C10: =Data!J26 -> 39300 | D10: =B10-C10 -> 15200 | E10: =D10/B10 -> 0.27889908 | H10: Average Monthly Expenses | J10: =AVERAGE(C5:C16) -> 44133.333
A11: July | B11: =Table2[[#This Row],[Total Income]] -> 82000 | C11: =Data!J27 -> 41600 | D11: =B11-C11 -> 40400 | E11: =D11/B11 -> 0.49268293 | H11: Average Monthly Savings | J11: =AVERAGE(D5:D16) -> 11200
A12: August | B12: =Table2[[#This Row],[Total Income]] -> 52000 | C12: =Data!J28 -> 37600 | D12: =B12-C12 -> 14400 | E12: =D12/B12 -> 0.27692308
A13: September | B13: =Table2[[#This Row],[Total Income]] -> 52000 | C13: =Data!J29 -> 63000 | D13: =B13-C13 -> -11000 | E13: =D13/B13 -> -0.21153846
A14: October | B14: =Table2[[#This Row],[Total Income]] -> 53000 | C14: =Data!J30 -> 39100 | D14: =B14-C14 -> 13900 | E14: =D14/B14 -> 0.26226415
A15: November | B15: =Table2[[#This Row],[Total Income]] -> 52000 | C15: =Data!J31 -> 36900 | D15: =B15-C15 -> 15100 | E15: =D15/B15 -> 0.29038462
A16: December | B16: =Table2[[#This Row],[Total Income]] -> 55000 | C16: =Data!J32 -> 44000 | D16: =B16-C16 -> 11000 | E16: =D16/B16 -> 0.2
A18: EXPENSE ANALYSIS | H18: CASH FLOW HEALTH INDICATORS
A19: Expense Category | C19: Annual Total | D19: % of Total Expenses | H19: KPI | J19: Formula
A20: Rent | C20: =Table3[[#Totals],[Rent]] -> 180000 | D20: =C20/$J$6 -> 0.33987915 | H20: Highest Income Month | J20: =INDEX(A5:A16,MATCH(MAX(B5:B16),B5:B16,0)) -> July
A21: Food | C21: =Table3[[#Totals],[Food]] -> 76200 | D21: =C21/$J$6 -> 0.14388218 | H21: Highest Expense Month | J21: =INDEX(A5:A16,MATCH(MAX(C5:C16),C5:C16,0)) -> March
A22: Utilities | C22: =Table3[[#Totals],[Utilities]] -> 32400 | D22: =C22/$J$6 -> 0.061178248 | H22: Highest Savings Month | J22: =INDEX(A5:A16,MATCH(MAX(D5:D16),D5:D16,0)) -> July
A23: Transport | C23: =Table3[[#Totals],[Transport]] -> 30900 | D23: =C23/$J$6 -> 0.058345921 | H23: Lowest Savings Month | J23: =INDEX(A5:A16,MATCH(MIN(D5:D16),D5:D16,0)) -> March
A24: Shopping | C24: =Table3[[#Totals],[Shopping]] -> 37000 | D24: =C24/$J$6 -> 0.069864048 | H24: Best Savings Rate | J24: =MAX(E5:E16) -> 0.49268293
A25: Entertainment | C25: =Table3[[#Totals],[Entertainment]] -> 29300 | D25: =C25/$J$6 -> 0.055324773 | H25: Worst Savings Rate | J25: =MIN(E5:E16) -> -0.53076923
A26: Parents | C26: =Table3[[#Totals],[Parents Support]] -> 60000 | D26: =C26/$J$6 -> 0.11329305 | H26: Months with Negative Savings | J26: =COUNTIF(D5:D16,"<0") -> 2
A27: Misc. | C27: =Table3[[#Totals],[Misc.]] -> 83800 | D27: =C27/$J$6 -> 0.15823263

Sheet Planning & Forecasting
A1: FINANCIAL PLANNING & SCENARIO ANALYSIS
A3: FINANCIAL GOAL PROGRESS | J3: EMERGENCY FUND PLANNER
A4: Goal | B4: Target Amount | C4: Monthly Saving Required | D4: Current Savings | E4: Remaining Amount | F4: Completion % | G4: Remaining % | H4: Status | J4: Item | K4: Value
A5: Emergency Fund | B5: =Data!B37 -> 150000 | C5: =Data!E37 -> 12500 | D5: 120000 | E5: =B5-D5 -> 30000 | F5: =D5/B5 -> 0.8 | G5: =E5/B5 -> 0.2 | H5: =IF(F5>=1,"Completed", IF(F5>=0.75,"On Track", IF(F5>=0.4,"In Progress", "Needs Attention"))) -> On Track | J5: Emergency Fund Target | K5: =Data!B37 -> 150000
A6: MBA Fund | B6: =Data!B39 -> 500000 | C6: =Data!E39 -> 13888.889 | D6: 14400 | E6: =B6-D6 -> 485600 | F6: =D6/B6 -> 0.0288 | G6: =E6/B6 -> 0.9712 | H6: =IF(F6>=1,"Completed", IF(F6>=0.75,"On Track", IF(F6>=0.4,"In Progress", "Needs Attention"))) -> Needs Attention | J6: Current Savings | K6: =D5 -> 120000
A7: Vacation | B7: =Data!B40 -> 30000 | C7: =Data!E40 -> 5000 | D7: 0 | E7: =B7-D7 -> 30000 | F7: =D7/B7 -> 0 | G7: =E7/B7 -> 1 | H7: =IF(F7>=1,"Completed", IF(F7>=0.75,"On Track", IF(F7>=0.4,"In Progress", "Needs Attention"))) -> Needs Attention | J7: Remaining Amount | K7: =K5-K6 -> 30000
A8: House Down Payment | B8: =Data!B41 -> 1000000 | C8: =Data!E41 -> 11904.762 | D8: 0 | E8: =B8-D8 -> 1000000 | F8: =D8/B8 -> 0 | G8: =E8/B8 -> 1 | H8: =IF(F8>=1,"Completed", IF(F8>=0.75,"On Track", IF(F8>=0.4,"In Progress", "Needs Attention"))) -> Needs Attention | J8: Average Monthly Savings | K8: =Analysis!J11 -> 11200
J9: Months Required | K9: =ROUNDUP(K7/K8,0) -> 3
J10: Expected Completion | K10: =EDATE(TODAY(),K9) -> 46295
J11: Status | K11: =IF(K6>=K5, "Fully Funded", "Building") -> Building
A13: FIVE-YEAR SAVINGS PROJECTION | F13: SCENARIO ANALYSIS
A14: Year | B14: Annual Income | C14: Annual Savings | D14: Cumulative Savings | F14: Scenario | G14: Savings Rate | H14: Annual Savings | I14: Years to Reach ₹10,00,000 | J14: Recommendation
A15: Year 1 | B15: =Analysis!J5 -> 664000 | C15: =Analysis!J7 -> 134400 | D15: =C15 -> 134400 | F15: Conservative | G15: 0.2 | H15: =Analysis!J5*0.2 -> 132800 | I15: =1000000/H15 -> 7.5301205 | J15: Suitable for maintaining current lifestyle, but long-term goals will take longer to achieve.
A16: Year 2 | B16: =B15*(1+0.08) -> 717120 | C16: =C15*(1+0.08) -> 145152 | D16: =D15+C16 -> 279552 | F16: Moderate | G16: 0.3 | H16: =Analysis!J5*0.3 -> 199200 | I16: =1000000/H16 -> 5.0200803 | J16: Provides a healthy balance between spending and saving while steadily progressing toward financial goals.
A17: Year 3 | B17: =B16*(1+0.08) -> 774489.6 | C17: =C16*(1+0.08) -> 156764.16 | D17: =D16+C17 -> 436316.16 | F17: Aggressive | G17: 0.4 | H17: =Analysis!J5*0.4 -> 265600 | I17: =1000000/H17 -> 3.7650602 | J17: Best for accelerating wealth creation, provided Priya can comfortably sustain a 40% savings rate.
A18: Year 4 | B18: =B17*(1+0.08) -> 836448.77 | C18: =C17*(1+0.08) -> 169305.29 | D18: =D17+C18 -> 605621.45
A19: Year 5 | B19: =B18*(1+0.08) -> 903364.67 | C19: =C18*(1+0.08) -> 182849.72 | D19: =D18+C19 -> 788471.17

Sheet Dashboards
A1: Financial Planning Dashboard – Priya Sharma
B3: ANNUAL INCOME | D3: ANNUAL EXPENSE | F3: ANNUAL SAVINGS | H3: SAVINGS RATE
B4: =Analysis!J5 -> 664000 | D4: =Analysis!J6 -> 529600 | F4: =Analysis!J7 -> 134400 | H4: =Analysis!J8 -> 0.20240964 | O4: KEY INSIGHTS
O5: •Emergency Fund is 80% complete and is projected to be fully funded by September 2026. •Rent represents 34% of annual expenses, making it the largest cost category. •March recorded a negative savings rate due to one-time high expenses. •At the current pace, Priya's cumulative savings could reach approximately ₹7.9 lakh in five years.
O20: RECOMMENDATIONS
O21: •Complete the Emergency Fund before increasing contributions to other goals. •Increase the savings rate from 20% toward 30% to accelerate long-term wealth creation. •Reduce discretionary spending on shopping and entertainment where practical. •Begin larger contributions to the MBA Fund after the Emergency Fund is completed.
